Workbook

Sheet ReadMe
A1: Created by: | B1: AT
A3: Tab Landscape Data contains the organizationname and state pairs from the landscape files. The variable mlr_name is my manual assignment of the corresponding MLR name.
A4: Tab MLR Data contains the MLR business state, company name, and group affiliation for observations where MLR was nonmissing and nonnegative.

Sheet Landscape Data
A1: state and org name | B1: state | C1: organizationname | D1: mlr_name_exact | E1: mlr_name
A2: =B2&" "&C2 -> OR PacificSource Medicare | B2: OR | C2: PacificSource Medicare | D2: =IFERROR(VLOOKUP(A2,'MLR Data'!$A$2:$D$706,4,0),"") | E2: PacificSource Health Plans
A3: =B3&" "&C3 -> VA Humana Insurance Company | B3: VA | C3: Humana Insurance Company | D3: =IFERROR(VLOOKUP(A3,'MLR Data'!$A$2:$D$706,4,0),"") | E3: Humana Insurance Company, Inc.
A4: =B4&" "&C4 -> MI Blue Cross Blue Shield of Michigan | B4: MI | C4: Blue Cross Blue Shield of Michigan | D4: =IFERROR(VLOOKUP(A4,'MLR Data'!$A$2:$D$706,4,0),"") -> Blue Cross Blue Shield of Michigan | E4: Blue Cross Blue Shield of Michigan
A5: =B5&" "&C5 -> NC Humana Insurance Company | B5: NC | C5: Humana Insurance Company | D5: =IFERROR(VLOOKUP(A5,'MLR Data'!$A$2:$D$706,4,0),"") | E5: Humana Insurance Company, Inc.
A6: =B6&" "&C6 -> WI Humana Insurance Company | B6: WI | C6: Humana Insurance Company | D6: =IFERROR(VLOOKUP(A6,'MLR Data'!$A$2:$D$706,4,0),"") | E6: Humana Insurance Company, Inc.
A7: =B7&" "&C7 -> MN Humana Insurance Company | B7: MN | C7: Humana Insurance Company | D7: =IFERROR(VLOOKUP(A7,'MLR Data'!$A$2:$D$706,4,0),"") | E7: Humana Insurance Company, Inc.
A8: =B8&" "&C8 -> OH Humana Insurance Company | B8: OH | C8: Humana Insurance Company | D8: =IFERROR(VLOOKUP(A8,'MLR Data'!$A$2:$D$706,4,0),"") | E8: Humana Insurance Company, Inc.
A9: =B9&" "&C9 -> GA Humana Insurance Company | B9: GA | C9: Humana Insurance Company | D9: =IFERROR(VLOOKUP(A9,'MLR Data'!$A$2:$D$706,4,0),"") | E9: Humana Insurance Company, Inc.
A10: =B10&" "&C10 -> MO Humana Insurance Company | B10: MO | C10: Humana Insurance Company | D10: =IFERROR(VLOOKUP(A10,'MLR Data'!$A$2:$D$706,4,0),"") | E10: Humana Insurance Company, Inc.
A11: =B11&" "&C11 -> IA Humana Insurance Company | B11: IA | C11: Humana Insurance Company | D11: =IFERROR(VLOOKUP(A11,'MLR Data'!$A$2:$D$706,4,0),"") | E11: Humana Insurance Company, Inc.
A12: =B12&" "&C12 -> IN Humana Insurance Company | B12: IN | C12: Humana Insurance Company | D12: =IFERROR(VLOOKUP(A12,'MLR Data'!$A$2:$D$706,4,0),"") | E12: Humana Insurance Company, Inc.
A13: =B13&" "&C13 -> OH Anthem Blue Cross and Blue Shield | B13: OH | C13: Anthem Blue Cross and Blue Shield | D13: =IFERROR(VLOOKUP(A13,'MLR Data'!$A$2:$D$706,4,0),"") | E13: Anthem Insurance Companies, Inc.
A14: =B14&" "&C14 -> FL WellCare | B14: FL | C14: WellCare | D14: =IFERROR(VLOOKUP(A14,'MLR Data'!$A$2:$D$706,4,0),"")
A15: =B15&" "&C15 -> PA Highmark Health Services | B15: PA | C15: Highmark Health Services | D15: =IFERROR(VLOOKUP(A15,'MLR Data'!$A$2:$D$706,4,0),"") | E15: Highmark, Inc.
A16: =B16&" "&C16 -> AR Humana Insurance Company | B16: AR | C16: Humana Insurance Company | D16: =IFERROR(VLOOKUP(A16,'MLR Data'!$A$2:$D$706,4,0),"") | E16: Humana Insurance Company, Inc.
A17: =B17&" "&C17 -> AL Blue Cross Blue Shield of Alabama | B17: AL | C17: Blue Cross Blue Shield of Alabama | D17: =IFERROR(VLOOKUP(A17,'MLR Data'!$A$2:$D$706,4,0),"") | E17: Blue Cross and Blue Shield of Alabama
A18: =B18&" "&C18 -> WI Unicare Life & Health Ins. Company | B18: WI | C18: Unicare Life & Health Ins. Company | D18: =IFERROR(VLOOKUP(A18,'MLR Data'!$A$2:$D$706,4,0),"") | E18: UNICARE Life & Health Insurance Company
A19: =B19&" "&C19 -> FL Freedom Health, Inc. | B19: FL | C19: Freedom Health, Inc. | D19: =IFERROR(VLOOKUP(A19,'MLR Data'!$A$2:$D$706,4,0),"")
A20: =B20&" "&C20 -> KY Humana Insurance Company | B20: KY | C20: Humana Insurance Company | D20: =IFERROR(VLOOKUP(A20,'MLR Data'!$A$2:$D$706,4,0),"") | E20: Humana Insurance Company, Inc.
A21: =B21&" "&C21 -> TN BlueCross BlueShield of Tennessee | B21: TN | C21: BlueCross BlueShield of Tennessee | D21: =IFERROR(VLOOKUP(A21,'MLR Data'!$A$2:$D$706,4,0),"") | E21: BlueCross BlueShield of Tennessee, Inc.
A22: =B22&" "&C22 -> TN Humana Insurance Company | B22: TN | C22: Humana Insurance Company | D22: =IFERROR(VLOOKUP(A22,'MLR Data'!$A$2:$D$706,4,0),"") | E22: Humana Insurance Company, Inc.
A23: =B23&" "&C23 -> SC Humana Insurance Company | B23: SC | C23: Humana Insurance Company | D23: =IFERROR(VLOOKUP(A23,'MLR Data'!$A$2:$D$706,4,0),"") | E23: Humana Insurance Company, Inc.
A24: =B24&" "&C24 -> TX Humana Insurance Company | B24: TX | C24: Humana Insurance Company | D24: =IFERROR(VLOOKUP(A24,'MLR Data'!$A$2:$D$706,4,0),"") | E24: Humana Health Plan of Texas, Inc.
A25: =B25&" "&C25 -> FL Universal Health Care, Inc. | B25: FL | C25: Universal Health Care, Inc. | D25: =IFERROR(VLOOKUP(A25,'MLR Data'!$A$2:$D$706,4,0),"")
A26: =B26&" "&C26 -> PA Humana Insurance Company | B26: PA | C26: Humana Insurance Company | D26: =IFERROR(VLOOKUP(A26,'MLR Data'!$A$2:$D$706,4,0),"") | E26: Humana Insurance Company, Inc.
A27: =B27&" "&C27 -> MI Humana Insurance Company | B27: MI | C27: Humana Insurance Company | D27: =IFERROR(VLOOKUP(A27,'MLR Data'!$A$2:$D$706,4,0),"") | E27: Humana Insurance Company, Inc.
A28: =B28&" "&C28 -> PA HealthAmerica Advantra | B28: PA | C28: HealthAmerica Advantra | D28: =IFERROR(VLOOKUP(A28,'MLR Data'!$A$2:$D$706,4,0),"") | E28: HealthAmerica Pennsylvania, Inc.
A29: =B29&" "&C29 -> NJ Horizon Blue Cross Blue Shield of New Jersey, Inc. | B29: NJ | C29: Horizon Blue Cross Blue Shield of New Jersey, Inc. | D29: =IFERROR(VLOOKUP(A29,'MLR Data'!$A$2:$D$706,4,0),"") | E29: Horizon Healthcare of New Jersey
A30: =B30&" "&C30 -> MN Medica Health Plans | B30: MN | C30: Medica Health Plans | D30: =IFERROR(VLOOKUP(A30,'MLR Data'!$A$2:$D$706,4,0),"") -> Medica Health Plans | E30: Medica Health Plans
A31: =B31&" "&C31 -> NC SecureHorizons by UnitedHealthcare | B31: NC | C31: SecureHorizons by UnitedHealthcare | D31: =IFERROR(VLOOKUP(A31,'MLR Data'!$A$2:$D$706,4,0),"") | E31: UnitedHealthcare Insurance Company
A32: =B32&" "&C32 -> MN UCare | B32: MN | C32: UCare | D32: =IFERROR(VLOOKUP(A32,'MLR Data'!$A$2:$D$706,4,0),"")
A33: =B33&" "&C33 -> PA UPMC Health Plan | B33: PA | C33: UPMC Health Plan | D33: =IFERROR(VLOOKUP(A33,'MLR Data'!$A$2:$D$706,4,0),"") | E33: UPMC Health Plan, Inc.
A34: =B34&" "&C34 -> IL Humana Insurance Company | B34: IL | C34: Humana Insurance Company | D34: =IFERROR(VLOOKUP(A34,'MLR Data'!$A$2:$D$706,4,0),"") | E34: Humana Insurance Company, Inc.
A35: =B35&" "&C35 -> MS Humana Insurance Company | B35: MS | C35: Humana Insurance Company | D35: =IFERROR(VLOOKUP(A35,'MLR Data'!$A$2:$D$706,4,0),"") | E35: Humana Insurance Company, Inc.
A36: =B36&" "&C36 -> NJ Aetna Medicare | B36: NJ | C36: Aetna Medicare | D36: =IFERROR(VLOOKUP(A36,'MLR Data'!$A$2:$D$706,4,0),"") | E36: Aetna Health Inc. (a New Jersey corporation)
A37: =B37&" "&C37 -> TN Cariten Health Plan, Inc. | B37: TN | C37: Cariten Health Plan, Inc. | D37: =IFERROR(VLOOKUP(A37,'MLR Data'!$A$2:$D$706,4,0),"")
A38: =B38&" "&C38 -> MN Medica Insurance Company | B38: MN | C38: Medica Insurance Company | D38: =IFERROR(VLOOKUP(A38,'MLR Data'!$A$2:$D$706,4,0),"") -> Medica Insurance Company | E38: Medica Insurance Company
A39: =B39&" "&C39 -> OK Humana Insurance Company | B39: OK | C39: Humana Insurance Company | D39: =IFERROR(VLOOKUP(A39,'MLR Data'!$A$2:$D$706,4,0),"") | E39: Humana Insurance Company, Inc.
A40: =B40&" "&C40 -> CO Humana Insurance Company | B40: CO | C40: Humana Insurance Company | D40: =IFERROR(VLOOKUP(A40,'MLR Data'!$A$2:$D$706,4,0),"") | E40: Humana Health Plan, Inc.
...

Sheet MLR Data
A1: state and company | B1: business_state | C1: state_code | D1: company_name | E1: group_affiliation
A2: =C2&" "&D2 -> AL Aetna Life Insurance Company | B2: Alabama | C2: AL | D2: Aetna Life Insurance Company | E2: Aetna Inc
A3: =C3&" "&D3 -> AL Blue Cross and Blue Shield of Alabama | B3: Alabama | C3: AL | D3: Blue Cross and Blue Shield of Alabama | E3: Blue Cross and Blue Shield of Alabama
A4: =C4&" "&D4 -> AL Celtic Insurance Company | B4: Alabama | C4: AL | D4: Celtic Insurance Company | E4: CeltiCare
A5: =C5&" "&D5 -> AL Connecticut General Life Insurance Company | B5: Alabama | C5: AL | D5: Connecticut General Life Insurance Company | E5: Cigna Hlth Grp
A6: =C6&" "&D6 -> AL HealthSpring of Alabama, Inc. | B6: Alabama | C6: AL | D6: HealthSpring of Alabama, Inc. | E6: HealthSpring, Inc.
A7: =C7&" "&D7 -> AL Humana Health Plan, Inc. | B7: Alabama | C7: AL | D7: Humana Health Plan, Inc. | E7: HUMANA GRP
A8: =C8&" "&D8 -> AL Humana Insurance Company, Inc. | B8: Alabama | C8: AL | D8: Humana Insurance Company, Inc. | E8: HUMANA GRP
A9: =C9&" "&D9 -> AL PacifiCare Life and Health Insurance Co | B9: Alabama | C9: AL | D9: PacifiCare Life and Health Insurance Co | E9: UnitedHealth Grp
A10: =C10&" "&D10 -> AL Sierra Health and Life Insurance Company, Inc. | B10: Alabama | C10: AL | D10: Sierra Health and Life Insurance Company, Inc. | E10: UnitedHealth Grp
A11: =C11&" "&D11 -> AL UNICARE Life & Health Insurance Company | B11: Alabama | C11: AL | D11: UNICARE Life & Health Insurance Company | E11: Wellpoint Inc Grp
A12: =C12&" "&D12 -> AL United American Insurance Co | B12: Alabama | C12: AL | D12: United American Insurance Co | E12: LIBERTY NATL GRP
A13: =C13&" "&D13 -> AL UnitedHealthcare Insurance Company | B13: Alabama | C13: AL | D13: UnitedHealthcare Insurance Company | E13: UnitedHealth Group
A14: =C14&" "&D14 -> AL UnitedHealthcare of Alabama, Inc | B14: Alabama | C14: AL | D14: UnitedHealthcare of Alabama, Inc | E14: UnitedHealth Group
A15: =C15&" "&D15 -> AL VIVA Health, Inc. | B15: Alabama | C15: AL | D15: VIVA Health, Inc.
A16: =C16&" "&D16 -> AK Aetna Life Insurance Company | B16: Alaska | C16: AK | D16: Aetna Life Insurance Company | E16: Aetna Inc
A17: =C17&" "&D17 -> AK Connecticut General Life Insurance Company | B17: Alaska | C17: AK | D17: Connecticut General Life Insurance Company | E17: Cigna Hlth Grp
A18: =C18&" "&D18 -> AK Humana Insurance Company, Inc. | B18: Alaska | C18: AK | D18: Humana Insurance Company, Inc. | E18: HUMANA GRP
A19: =C19&" "&D19 -> AK United American Insurance Co | B19: Alaska | C19: AK | D19: United American Insurance Co | E19: LIBERTY NATL GRP
A20: =C20&" "&D20 -> AK UnitedHealthcare Insurance Company | B20: Alaska | C20: AK | D20: UnitedHealthcare Insurance Company | E20: UnitedHealth Group
A21: =C21&" "&D21 -> AZ Aetna Health Inc. (a Pennsylvania corporation) | B21: Arizona | C21: AZ | D21: Aetna Health Inc. (a Pennsylvania corporation) | E21: Aetna Inc
A22: =C22&" "&D22 -> AZ Aetna Life Insurance Company | B22: Arizona | C22: AZ | D22: Aetna Life Insurance Company | E22: Aetna Inc
A23: =C23&" "&D23 -> AZ Celtic Insurance Company | B23: Arizona | C23: AZ | D23: Celtic Insurance Company | E23: CeltiCare
A24: =C24&" "&D24 -> AZ Cigna HealthCare of Arizona, Inc. | B24: Arizona | C24: AZ | D24: Cigna HealthCare of Arizona, Inc. | E24: Cigna Hlth Grp
A25: =C25&" "&D25 -> AZ Connecticut General Life Insurance Company | B25: Arizona | C25: AZ | D25: Connecticut General Life Insurance Company | E25: Cigna Hlth Grp
A26: =C26&" "&D26 -> AZ Health Net Life Insurance Company | B26: Arizona | C26: AZ | D26: Health Net Life Insurance Company | E26: Health Net Inc. Grp
A27: =C27&" "&D27 -> AZ Health Net of Arizona, Inc | B27: Arizona | C27: AZ | D27: Health Net of Arizona, Inc | E27: Health Net Inc. Grp
... A45: =C45&" "&D45 -> AR UnitedHealthcare of Arkansas, Inc. | B45: Arkansas | C45: AR | D45: UnitedHealthcare of Arkansas, Inc. | E45: UnitedHealth Group
A46: =C46&" "&D46 -> CA Aetna Health of California Inc. | B46: California | C46: CA | D46: Aetna Health of California Inc.
A47: =C47&" "&D47 -> CA Aetna Life Insurance Company | B47: California | C47: CA | D47: Aetna Life Insurance Company | E47: Aetna Inc
A48: =C48&" "&D48 -> CA Anthem Blue Cross Life and Health Insurance Company, Inc. | B48: California | C48: CA | D48: Anthem Blue Cross Life and Health Insurance Company, Inc. | E48: WellPoint Inc Grp
A49: =C49&" "&D49 -> CA Blue Cross of California | B49: California | C49: CA | D49: Blue Cross of California
A50: =C50&" "&D50 -> CA California Physicians Service | B50: California | C50: CA | D50: California Physicians Service | E50: Blue Shield of California Group
A51: =C51&" "&D51 -> CA Celtic Insurance Company | B51: California | C51: CA | D51: Celtic Insurance Company | E51: CeltiCare
A52: =C52&" "&D52 -> CA Chinese Community Health Plan | B52: California | C52: CA | D52: Chinese Community Health Plan
A53: =C53&" "&D53 -> CA Connecticut General Life Insurance Company | B53: California | C53: CA | D53: Connecticut General Life Insurance Company | E53: Cigna Hlth Grp
A54: =C54&" "&D54 -> CA County of Ventura, dba Ventura County Health Care Plan | B54: California | C54: CA | D54: County of Ventura, dba Ventura County Health Care Plan
A55: =C55&" "&D55 -> CA Health Net Life Insurance Company | B55: California | C55: CA | D55: Health Net Life Insurance Company | E55: Health Net Inc. Grp
A56: =C56&" "&D56 -> CA Health Net of California, Inc | B56: California | C56: CA | D56: Health Net of California, Inc | E56: Health Net Inc. Grp
A57: =C57&" "&D57 -> CA Humana Insurance Company, Inc. | B57: California | C57: CA | D57: Humana Insurance Company, Inc. | E57: HUMANA GRP
...
